Workbook

Sheet Accueil
A1: Pharmacie — Ventes 2014 à 2019
A2: Historique du 02/01/2014 au 08/10/2019
A3: Cliquez sur un bouton pour ouvrir l'onglet correspondant.
A5: PROPRIÉTAIRE | G5: PHARMACIEN
A7: =HYPERLINK("#Activite!A1","Activité de la pharmacie") -> Activité de la pharmacie | G7: =HYPERLINK("#Stocks!A1","Stocks et alertes") -> Stocks et alertes
A8: =HYPERLINK("#Environnement!A1","Environnement de la pharmacie") -> Environnement de la pharmacie | G8: =HYPERLINK("#Scan!A1","Scan des ventes") -> Scan des ventes
A11: OUTILS COMMUNS
A12: =HYPERLINK("#Recherche!A1","Recherche") -> Recherche | D12: =HYPERLINK("#Calendrier!A1","Calendrier") -> Calendrier | G12: =HYPERLINK("#Statistiques!A1","Statistiques") -> Statistiques | J12: =HYPERLINK("#Qualite_donnees!A1","Qualité des données") -> Qualité des données
A14: ALERTES DE STOCK
A15: MÉDICAMENTS EN RUPTURE | G15: MÉDICAMENTS À COMMANDER
A16: =COUNTIF(Stocks!$K$8:$K$15,"RUPTURE") -> 0 | G16: =COUNTIF(Stocks!$K$8:$K$15,"À COMMANDER") -> 0
A17: Dépend du stock saisi dans l'onglet Stocks.
A19: Chiffres clés sur tout l'historique
A20: Volume total vendu | E20: Ventes par jour | I20: ="Groupe n°1 : "&ROUND(MAX(Calculs!$C$60:$C$67)/SUM(Calculs!$C$60:$C$67)*100,0)&" % des ventes" -> Groupe n°1 : 50 % des ventes
A21: =SUMIFS(Historique!$Y$2:$Y$2107,Historique!$H$2:$H$2107,"Oui") -> 129048.33 | E21: =IFERROR(A21/COUNTIF(Historique!$H$2:$H$2107,"Oui"),0) -> 61.334756 | I21: =INDEX(Calculs!$A$60:$A$67,MATCH(MAX(Calculs!$C$60:$C$67),Calculs!$C$60:$C$67,0)) -> N02BE

Sheet Activite
A1: Tableau de bord de l'activité | L1: =HYPERLINK("#Accueil!A1","← Accueil") -> ← Accueil | M1: =HYPERLINK("#Environnement!A1","Environnement") -> Environnement | N1: =HYPERLINK("#Recherche!A1","Recherche") -> Recherche
A2: Choisissez une année, un mois et un médicament dans les cases jaunes (▼) : indicateurs et graphiques se mettent à jour.
A4: Année | B4: Toutes | C4: Mois | D4: Tous | E4: Médicament | G4: Tous
A6: Total vendu | D6: Journées ouvertes | F6: Ventes par jour | H6: =IF($D$4="Tous","Mois le plus fort","Meilleure année") -> Mois le plus fort | J6: Jour le plus fort | L6: Heure de pointe
A7: =SUMIFS(INDEX(Historique!$I$2:$Y$2107,0,Calculs!$C$73),Historique!$B$2:$B$2107,Calculs!$C$71,Historique!$C$2:$C$2107,Calculs!$C$74,Historique!$H$2:$H$2107,"Oui") -> 129048.33 | D7: =COUNTIFS(Historique!$B$2:$B$2107,Calculs!$C$71,Historique!$C$2:$C$2107,Calculs!$C$74,Historique!$H$2:$H$2107,"Oui") -> 2104 | F7: =IFERROR(A7/D7,0) -> 61.334756 | H7: =IF($D$4="Tous",INDEX(Calculs!$A$147:$A$158,MATCH(MAX(Calculs!$B$147:$B$158),Calculs!$B$147:$B$158,0)),INDEX(Calculs!$A$201:$A$206,MATCH(MAX(Calculs!$B$201:$B$206),Calculs!$B$201:$B$206,0))) -> Janv. | J7: =INDEX(Calculs!$A$162:$A$168,MATCH(MAX(Calculs!$B$162:$B$168),Calculs!$B$162:$B$168,0)) -> Sam. | L7: =INDEX(Calculs!$A$172:$A$186,MATCH(MAX(Calculs!$B$172:$B$186),Calculs!$B$172:$B$186,0)) -> 19h
A74: Évolution mois par mois : suit le médicament. Saisonnalité : suit l'année et le médicament. Les autres graphiques suivent aussi le mois choisi.
A75: Quantités dans l'unité du logiciel de caisse ; l'export ne contient aucun prix.
A77: Mois par mois
A78: Mesure | B78: Total vendu
A80: Mois | B80: 2014 | C80: 2015 | D80: 2016 | E80: 2017 | F80: 2018 | G80: 2019
A81: Janvier | B81: =IF(AA81<AH81,"",IF($B$78="Total vendu",T81,T81/AA81)) | C81: =IF(AB81<AI81,"",IF($B$78="Total vendu",U81,U81/AB81)) -> 2297.455 | D81: =IF(AC81<AJ81,"",IF($B$78="Total vendu",V81,V81/AC81)) -> 2650.792 | E81: =IF(AD81<AK81,"",IF($B$78="Total vendu",W81,W81/AD81)) -> 2437.102 | F81: =IF(AE81<AL81,"",IF($B$78="Total vendu",X81,X81/AE81)) -> 2158.996 | G81: =IF(AF81<AM81,"",IF($B$78="Total vendu",Y81,Y81/AF81)) -> 3102.223 | T81: =SUMIFS(INDEX(Historique!$I$2:$Y$2107,0,Calculs!$C$73),Historique!$B$2:$B$2107,2014,Historique!$C$2:$C$2107,1) -> 1858.6 | U81: =SUMIFS(INDEX(Historique!$I$2:$Y$2107,0,Calculs!$C$73),Historique!$B$2:$B$2107,2015,Historique!$C$2:$C$2107,1) -> 2297.455 | V81: =SUMIFS(INDEX(Historique!$I$2:$Y$2107,0,Calculs!$C$73),Historique!$B$2:$B$2107,2016,Historique!$C$2:$C$2107,1) -> 2650.792 | W81: =SUMIFS(INDEX(Historique!$I$2:$Y$2107,0,Calculs!$C$73),Historique!$B$2:$B$2107,2017,Historique!$C$2:$C$2107,1) -> 2437.102 | X81: =SUMIFS(INDEX(Historique!$I$2:$Y$2107,0,Calculs!$C$73),Historique!$B$2:$B$2107,2018,Historique!$C$2:$C$2107,1) -> 2158.996 | Y81: =SUMIFS(INDEX(Historique!$I$2:$Y$2107,0,Calculs!$C$73),Historique!$B$2:$B$2107,2019,Historique!$C$2:$C$2107,1) -> 3102.223 | AA81: =COUNTIFS(Historique!$B$2:$B$2107,2014,Historique!$C$2:$C$2107,1) -> 30 | AB81: =COUNTIFS(Historique!$B$2:$B$2107,2015,Historique!$C$2:$C$2107,1) -> 31 | AC81: =COUNTIFS(Historique!$B$2:$B$2107,2016,Historique!$C$2:$C$2107,1) -> 31 | AD81: =COUNTIFS(Historique!$B$2:$B$2107,2017,Historique!$C$2:$C$2107,1) -> 31 | AE81: =COUNTIFS(Historique!$B$2:$B$2107,2018,Historique!$C$2:$C$2107,1) -> 31 | AF81: =COUNTIFS(Historique!$B$2:$B$2107,2019,Historique!$C$2:$C$2107,1) -> 31 | AH81: =DAY(DATE(2014,2,0)) -> 31 | AI81: =DAY(DATE(2015,2,0)) -> 31 | AJ81: =DAY(DATE(2016,2,0)) -> 31 | AK81: =DAY(DATE(2017,2,0)) -> 31 | AL81: =DAY(DATE(2018,2,0)) -> 31 | AM81: =DAY(DATE(2019,2,0)) -> 31
A82: Février | B82: =IF(AA82<AH82,"",IF($B$78="Total vendu",T82,T82/AA82)) -> 1974.47 | C82: =IF(AB82<AI82,"",IF($B$78="Total vendu",U82,U82/AB82)) -> 1831.532 | D82: =IF(AC82<AJ82,"",IF($B$78="Total vendu",V82,V82/AC82)) -> 2232.4 | E82: =IF(AD82<AK82,"",IF($B$78="Total vendu",W82,W82/AD82)) -> 1440.491 | F82: =IF(AE82<AL82,"",IF($B$78="Total vendu",X82,X82/AE82)) -> 2174.498 | G82: =IF(AF82<AM82,"",IF($B$78="Total vendu",Y82,Y82/AF82)) -> 1944.197 | T82: =SUMIFS(INDEX(Historique!$I$2:$Y$2107,0,Calculs!$C$73),Historique!$B$2:$B$2107,2014,Historique!$C$2:$C$2107,2) -> 1974.47 | U82: =SUMIFS(INDEX(Historique!$I$2:$Y$2107,0,Calculs!$C$73),Historique!$B$2:$B$2107,2015,Historique!$C$2:$C$2107,2) -> 1831.532 | V82: =SUMIFS(INDEX(Historique!$I$2:$Y$2107,0,Calculs!$C$73),Historique!$B$2:$B$2107,2016,Historique!$C$2:$C$2107,2) -> 2232.4 | W82: =SUMIFS(INDEX(Historique!$I$2:$Y$2107,0,Calculs!$C$73),Historique!$B$2:$B$2107,2017,Historique!$C$2:$C$2107,2) -> 1440.491 | X82: =SUMIFS(INDEX(Historique!$I$2:$Y$2107,0,Calculs!$C$73),Historique!$B$2:$B$2107,2018,Historique!$C$2:$C$2107,2) -> 2174.498 | Y82: =SUMIFS(INDEX(Historique!$I$2:$Y$2107,0,Calculs!$C$73),Historique!$B$2:$B$2107,2019,Historique!$C$2:$C$2107,2) -> 1944.197 | AA82: =COUNTIFS(Historique!$B$2:$B$2107,2014,Historique!$C$2:$C$2107,2) -> 28 | AB82: =COUNTIFS(Historique!$B$2:$B$2107,2015,Historique!$C$2:$C$2107,2) -> 28 | AC82: =COUNTIFS(Historique!$B$2:$B$2107,2016,Historique!$C$2:$C$2107,2) -> 29 | AD82: =COUNTIFS(Historique!$B$2:$B$2107,2017,Historique!$C$2:$C$2107,2) -> 28 | AE82: =COUNTIFS(Historique!$B$2:$B$2107,2018,Historique!$C$2:$C$2107,2) -> 28 | AF82: =COUNTIFS(Historique!$B$2:$B$2107,2019,Historique!$C$2:$C$2107,2) -> 28 | AH82: =DAY(DATE(2014,3,0)) -> 28 | AI82: =DAY(DATE(2015,3,0)) -> 28 | AJ82: =DAY(DATE(2016,3,0)) -> 29 | AK82: =DAY(DATE(2017,3,0)) -> 28 | AL82: =DAY(DATE(2018,3,0)) -> 28 | AM82: =DAY(DATE(2019,3,0)) -> 28
A83: Mars | B83: =IF(AA83<AH83,"",IF($B$78="Total vendu",T83,T83/AA83)) -> 1606.72 | C83: =IF(AB83<AI83,"",IF($B$78="Total vendu",U83,U83/AB83)) -> 1949.076 | D83: =IF(AC83<AJ83,"",IF($B$78="Total vendu",V83,V83/AC83)) -> 2235.169 | E83: =IF(AD83<AK83,"",IF($B$78="Total vendu",W83,W83/AD83)) -> 1376.855 | F83: =IF(AE83<AL83,"",IF($B$78="Total vendu",X83,X83/AE83)) -> 2156.847 | G83: =IF(AF83<AM83,"",IF($B$78="Total vendu",Y83,Y83/AF83)) -> 2038.938 | T83: =SUMIFS(INDEX(Historique!$I$2:$Y$2107,0,Calculs!$C$73),Historique!$B$2:$B$2107,2014,Historique!$C$2:$C$2107,3) -> 1606.72 | U83: =SUMIFS(INDEX(Historique!$I$2:$Y$2107,0,Calculs!$C$73),Historique!$B$2:$B$2107,2015,Historique!$C$2:$C$2107,3) -> 1949.076 | V83: =SUMIFS(INDEX(Historique!$I$2:$Y$2107,0,Calculs!$C$73),Historique!$B$2:$B$2107,2016,Historique!$C$2:$C$2107,3) -> 2235.169 | W83: =SUMIFS(INDEX(Historique!$I$2:$Y$2107,0,Calculs!$C$73),Historique!$B$2:$B$2107,2017,Historique!$C$2:$C$2107,3) -> 1376.855 | X83: =SUMIFS(INDEX(Historique!$I$2:$Y$2107,0,Calculs!$C$73),Historique!$B$2:$B$2107,2018,Historique!$C$2:$C$2107,3) -> 2156.847 | Y83: =SUMIFS(INDEX(Historique!$I$2:$Y$2107,0,Calculs!$C$73),Historique!$B$2:$B$2107,2019,Historique!$C$2:$C$2107,3) -> 2038.938 | AA83: =COUNTIFS(Historique!$B$2:$B$2107,2014,Historique!$C$2:$C$2107,3) -> 31 | AB83: =COUNTIFS(Historique!$B$2:$B$2107,2015,Historique!$C$2:$C$2107,3) -> 31 | AC83: =COUNTIFS(Historique!$B$2:$B$2107,2016,Historique!$C$2:$C$2107,3) -> 31 | AD83: =COUNTIFS(Historique!$B$2:$B$2107,2017,Historique!$C$2:$C$2107,3) -> 31 | AE83: =COUNTIFS(Historique!$B$2:$B$2107,2018,Historique!$C$2:$C$2107,3) -> 31 | AF83: =COUNTIFS(Historique!$B$2:$B$2107,2019,Historique!$C$2:$C$2107,3) -> 31 | AH83: =DAY(DATE(2014,4,0)) -> 31 | AI83: =DAY(DATE(2015,4,0)) -> 31 | AJ83: =DAY(DATE(2016,4,0)) -> 31 | AK83: =DAY(DATE(2017,4,0)) -> 31 | AL83: =DAY(DATE(2018,4,0)) -> 31 | AM83: =DAY(DATE(2019,4,0)) -> 31
A84: Avril | B84: =IF(AA84<AH84,"",IF($B$78="Total vendu",T84,T84/AA84)) -> 1465.265 | C84: =IF(AB84<AI84,"",IF($B$78="Total vendu",U84,U84/AB84)) -> 1821.465 | D84: =IF(AC84<AJ84,"",IF($B$78="Total vendu",V84,V84/AC84)) -> 2147.573 | E84: =IF(AD84<AK84,"",IF($B$78="Total vendu",W84,W84/AD84)) -> 1413.846 | F84: =IF(AE84<AL84,"",IF($B$78="Total vendu",X84,X84/AE84)) -> 1930.689 | G84: =IF(AF84<AM84,"",IF($B$78="Total vendu",Y84,Y84/AF84)) -> 1822.673 | T84: =SUMIFS(INDEX(Historique!$I$2:$Y$2107,0,Calculs!$C$73),Historique!$B$2:$B$2107,2014,Historique!$C$2:$C$2107,4) -> 1465.265 | U84: =SUMIFS(INDEX(Historique!$I$2:$Y$2107,0,Calculs!$C$73),Historique!$B$2:$B$2107,2015,Historique!$C$2:$C$2107,4) -> 1821.465 | V84: =SUMIFS(INDEX(Historique!$I$2:$Y$2107,0,Calculs!$C$73),Historique!$B$2:$B$2107,2016,Historique!$C$2:$C$2107,4) -> 2147.573 | W84: =SUMIFS(INDEX(Historique!$I$2:$Y$2107,0,Calculs!$C$73),Historique!$B$2:$B$2107,2017,Historique!$C$2:$C$2107,4) -> 1413.846 | X84: =SUMIFS(INDEX(Historique!$I$2:$Y$2107,0,Calculs!$C$73),Historique!$B$2:$B$2107,2018,Historique!$C$2:$C$2107,4) -> 1930.689 | Y84: =SUMIFS(INDEX(Historique!$I$2:$Y$2107,0,Calculs!$C$73),Historique!$B$2:$B$2107,2019,Historique!$C$2:$C$2107,4) -> 1822.673 | AA84: =COUNTIFS(Historique!$B$2:$B$2107,2014,Historique!$C$2:$C$2107,4) -> 30 | AB84: =COUNTIFS(Historique!$B$2:$B$2107,2015,Historique!$C$2:$C$2107,4) -> 30 | AC84: =COUNTIFS(Historique!$B$2:$B$2107,2016,Historique!$C$2:$C$2107,4) -> 30 | AD84: =COUNTIFS(Historique!$B$2:$B$2107,2017,Historique!$C$2:$C$2107,4) -> 30 | AE84: =COUNTIFS(Historique!$B$2:$B$2107,2018,Historique!$C$2:$C$2107,4) -> 30 | AF84: =COUNTIFS(Historique!$B$2:$B$2107,2019,Historique!$C$2:$C$2107,4) -> 30 | AH84: =DAY(DATE(2014,5,0)) -> 30 | AI84: =DAY(DATE(2015,5,0)) -> 30 | AJ84: =DAY(DATE(2016,5,0)) -> 30 | AK84: =DAY(DATE(2017,5,0)) -> 30 | AL84: =DAY(DATE(2018,5,0)) -> 30 | AM84: =DAY(DATE(2019,5,0)) -> 30
A85: Mai | B85: =IF(AA85<AH85,"",IF($B$78="Total vendu",T85,T85/AA85)) -> 1536.973 | C85: =IF(AB85<AI85,"",IF($B$78="Total vendu",U85,U85/AB85)) -> 1644.577 | D85: =IF(AC85<AJ85,"",IF($B$78="Total vendu",V85,V85/AC85)) -> 2006.081 | E85: =IF(AD85<AK85,"",IF($B$78="Total vendu",W85,W85/AD85)) -> 1369.485 | F85: =IF(AE85<AL85,"",IF($B$78="Total vendu",X85,X85/AE85)) -> 1650.13 | G85: =IF(AF85<AM85,"",IF($B$78="Total vendu",Y85,Y85/AF85)) -> 1798.4517 | T85: =SUMIFS(INDEX(Historique!$I$2:$Y$2107,0,Calculs!$C$73),Historique!$B$2:$B$2107,2014,Historique!$C$2:$C$2107,5) -> 1536.973 | U85: =SUMIFS(INDEX(Historique!$I$2:$Y$2107,0,Calculs!$C$73),Historique!$B$2:$B$2107,2015,Historique!$C$2:$C$2107,5) -> 1644.577 | V85: =SUMIFS(INDEX(Historique!$I$2:$Y$2107,0,Calculs!$C$73),Historique!$B$2:$B$2107,2016,Historique!$C$2:$C$2107,5) -> 2006.081 | W85: =SUMIFS(INDEX(Historique!$I$2:$Y$2107,0,Calculs!$C$73),Historique!$B$2:$B$2107,2017,Historique!$C$2:$C$2107,5) -> 1369.485 | X85: =SUMIFS(INDEX(Historique!$I$2:$Y$2107,0,Calculs!$C$73),Historique!$B$2:$B$2107,2018,Historique!$C$2:$C$2107,5) -> 1650.13 | Y85: =SUMIFS(INDEX(Historique!$I$2:$Y$2107,0,Calculs!$C$73),Historique!$B$2:$B$2107,2019,Historique!$C$2:$C$2107,5) -> 1798.4517 | AA85: =COUNTIFS(Historique!$B$2:$B$2107,2014,Historique!$C$2:$C$2107,5) -> 31 | AB85: =COUNTIFS(Historique!$B$2:$B$2107,2015,Historique!$C$2:$C$2107,5) -> 31 | AC85: =COUNTIFS(Historique!$B$2:$B$2107,2016,Historique!$C$2:$C$2107,5) -> 31 | AD85: =COUNTIFS(Historique!$B$2:$B$2107,2017,Historique!$C$2:$C$2107,5) -> 31 | AE85: =COUNTIFS(Historique!$B$2:$B$2107,2018,Historique!$C$2:$C$2107,5) -> 31 | AF85: =COUNTIFS(Historique!$B$2:$B$2107,2019,Historique!$C$2:$C$2107,5) -> 31 | AH85: =DAY(DATE(2014,6,0)) -> 31 | AI85: =DAY(DATE(2015,6,0)) -> 31 | AJ85: =DAY(DATE(2016,6,0)) -> 31 | AK85: =DAY(DATE(2017,6,0)) -> 31 | AL85: =DAY(DATE(2018,6,0)) -> 31 | AM85: =DAY(DATE(2019,6,0)) -> 31
A86: Juin | B86: =IF(AA86<AH86,"",IF($B$78="Total vendu",T86,T86/AA86)) -> 1390.205 | C86: =IF(AB86<AI86,"",IF($B$78="Total vendu",U86,U86/AB86)) -> 1674.233 | D86: =IF(AC86<AJ86,"",IF($B$78="Total vendu",V86,V86/AC86)) -> 1724.731 | E86: =IF(AD86<AK86,"",IF($B$78="Total vendu",W86,W86/AD86)) -> 1306.936 | F86: =IF(AE86<AL86,"",IF($B$78="Total vendu",X86,X86/AE86)) -> 1414.349 | G86: =IF(AF86<AM86,"",IF($B$78="Total vendu",Y86,Y86/AF86)) -> 1482.407 | T86: =SUMIFS(INDEX(Historique!$I$2:$Y$2107,0,Calculs!$C$73),Historique!$B$2:$B$2107,2014,Historique!$C$2:$C$2107,6) -> 1390.205 | U86: =SUMIFS(INDEX(Historique!$I$2:$Y$2107,0,Calculs!$C$73),Historique!$B$2:$B$2107,2015,Historique!$C$2:$C$2107,6) -> 1674.233 | V86: =SUMIFS(INDEX(Historique!$I$2:$Y$2107,0,Calculs!$C$73),Historique!$B$2:$B$2107,2016,Historique!$C$2:$C$2107,6) -> 1724.731 | W86: =SUMIFS(INDEX(Historique!$I$2:$Y$2107,0,Calculs!$C$73),Historique!$B$2:$B$2107,2017,Historique!$C$2:$C$2107,6) -> 1306.936 | X86: =SUMIFS(INDEX(Historique!$I$2:$Y$2107,0,Calculs!$C$73),Historique!$B$2:$B$2107,2018,Historique!$C$2:$C$2107,6) -> 1414.349 | Y86: =SUMIFS(INDEX(Historique!$I$2:$Y$2107,0,Calculs!$C$73),Historique!$B$2:$B$2107,2019,Historique!$C$2:$C$2107,6) -> 1482.407 | AA86: =COUNTIFS(Historique!$B$2:$B$2107,2014,Historique!$C$2:$C$2107,6) -> 30 | AB86: =COUNTIFS(Historique!$B$2:$B$2107,2015,Historique!$C$2:$C$2107,6) -> 30 | AC86: =COUNTIFS(Historique!$B$2:$B$2107,2016,Historique!$C$2:$C$2107,6) -> 30 | AD86: =COUNTIFS(Historique!$B$2:$B$2107,2017,Historique!$C$2:$C$2107,6) -> 30 | AE86: =COUNTIFS(Historique!$B$2:$B$2107,2018,Historique!$C$2:$C$2107,6) -> 30 | AF86: =COUNTIFS(Historique!$B$2:$B$2107,2019,Historique!$C$2:$C$2107,6) -> 30 | AH86: =DAY(DATE(2014,7,0)) -> 30 | AI86: =DAY(DATE(2015,7,0)) -> 30 | AJ86: =DAY(DATE(2016,7,0)) -> 30 | AK86: =DAY(DATE(2017,7,0)) -> 30 | AL86: =DAY(DATE(2018,7,0)) -> 30 | AM86: =DAY(DATE(2019,7,0)) -> 30
A87: Juillet | B87: =IF(AA87<AH87,"",IF($B$78="Total vendu",T87,T87/AA87)) -> 1332.37 | C87: =IF(AB87<AI87,"",IF($B$78="Total vendu",U87,U87/AB87)) -> 1523.048 | D87: =IF(AC87<AJ87,"",IF($B$78="Total vendu",V87,V87/AC87)) -> 1599.6393 | E87: =IF(AD87<AK87,"",IF($B$78="Total vendu",W87,W87/AD87)) -> 1251.151 | F87: =IF(AE87<AL87,"",IF($B$78="Total vendu",X87,X87/AE87)) -> 1563.479 | G87: =IF(AF87<AM87,"",IF($B$78="Total vendu",Y87,Y87/AF87)) -> 1488.816 | T87: =SUMIFS(INDEX(Historique!$I$2:$Y$2107,0,Calculs!$C$73),Historique!$B$2:$B$2107,2014,Historique!$C$2:$C$2107,7) -> 1332.37 | U87: =SUMIFS(INDEX(Historique!$I$2:$Y$2107,0,Calculs!$C$73),Historique!$B$2:$B$2107,2015,Historique!$C$2:$C$2107,7) -> 1523.048 | V87: =SUMIFS(INDEX(Historique!$I$2:$Y$2107,0,Calculs!$C$73),Historique!$B$2:$B$2107,2016,Historique!$C$2:$C$2107,7) -> 1599.6393 | W87: =SUMIFS(INDEX(Historique!$I$2:$Y$2107,0,Calculs!$C$73),Historique!$B$2:$B$2107,2017,Historique!$C$2:$C$2107,7) -> 1251.151 | X87: =SUMIFS(INDEX(Historique!$I$2:$Y$2107,0,Calculs!$C$73),Historique!$B$2:$B$2107,2018,Historique!$C$2:$C$2107,7) -> 1563.479 | Y87: =SUMIFS(INDEX(Historique!$I$2:$Y$2107,0,Calculs!$C$73),Historique!$B$2:$B$2107,2019,Historique!$C$2:$C$2107,7) -> 1488.816 | AA87: =COUNTIFS(Historique!$B$2:$B$2107,2014,Historique!$C$2:$C$2107,7) -> 31 | AB87: =COUNTIFS(Historique!$B$2:$B$2107,2015,Historique!$C$2:$C$2107,7) -> 31 | AC87: =COUNTIFS(Historique!$B$2:$B$2107,2016,Historique!$C$2:$C$2107,7) -> 31 | AD87: =COUNTIFS(Historique!$B$2:$B$2107,2017,Historique!$C$2:$C$2107,7) -> 31 | AE87: =COUNTIFS(Historique!$B$2:$B$2107,2018,Historique!$C$2:$C$2107,7) -> 31 | AF87: =COUNTIFS(Historique!$B$2:$B$2107,2019,Historique!$C$2:$C$2107,7) -> 31 | AH87: =DAY(DATE(2014,8,0)) -> 31 | AI87: =DAY(DATE(2015,8,0)) -> 31 | AJ87: =DAY(DATE(2016,8,0)) -> 31 | AK87: =DAY(DATE(2017,8,0)) -> 31 | AL87: =DAY(DATE(2018,8,0)) -> 31 | AM87: =DAY(DATE(2019,8,0)) -> 31
A88: Août | B88: =IF(AA88<AH88,"",IF($B$78="Total vendu",T88,T88/AA88)) -> 1452.52 | C88: =IF(AB88<AI88,"",IF($B$78="Total vendu",U88,U88/AB88)) -> 1659.597 | D88: =IF(AC88<AJ88,"",IF($B$78="Total vendu",V88,V88/AC88)) -> 1633.3883 | E88: =IF(AD88<AK88,"",IF($B$78="Total vendu",W88,W88/AD88)) -> 1302.42 | F88: =IF(AE88<AL88,"",IF($B$78="Total vendu",X88,X88/AE88)) -> 1611.907 | G88: =IF(AF88<AM88,"",IF($B$78="Total vendu",Y88,Y88/AF88)) -> 1377.779 | T88: =SUMIFS(INDEX(Historique!$I$2:$Y$2107,0,Calculs!$C$73),Historique!$B$2:$B$2107,2014,Historique!$C$2:$C$2107,8) -> 1452.52 | U88: =SUMIFS(INDEX(Historique!$I$2:$Y$2107,0,Calculs!$C$73),Historique!$B$2:$B$2107,2015,Historique!$C$2:$C$2107,8) -> 1659.597 | V88: =SUMIFS(INDEX(Historique!$I$2:$Y$2107,0,Calculs!$C$73),Historique!$B$2:$B$2107,2016,Historique!$C$2:$C$2107,8) -> 1633.3883 | W88: =SUMIFS(INDEX(Historique!$I$2:$Y$2107,0,Calculs!$C$73),Historique!$B$2:$B$2107,2017,Historique!$C$2:$C$2107,8) -> 1302.42 | X88: =SUMIFS(INDEX(Historique!$I$2:$Y$2107,0,Calculs!$C$73),Historique!$B$2:$B$2107,2018,Historique!$C$2:$C$2107,8) -> 1611.907 | Y88: =SUMIFS(INDEX(Historique!$I$2:$Y$2107,0,Calculs!$C$73),Historique!$B$2:$B$2107,2019,Historique!$C$2:$C$2107,8) -> 1377.779 | AA88: =COUNTIFS(Historique!$B$2:$B$2107,2014,Historique!$C$2:$C$2107,8) -> 31 | AB88: =COUNTIFS(Historique!$B$2:$B$2107,2015,Historique!$C$2:$C$2107,8) -> 31 | AC88: =COUNTIFS(Historique!$B$2:$B$2107,2016,Historique!$C$2:$C$2107,8) -> 31 | AD88: =COUNTIFS(Historique!$B$2:$B$2107,2017,Historique!$C$2:$C$2107,8) -> 31 | AE88: =COUNTIFS(Historique!$B$2:$B$2107,2018,Historique!$C$2:$C$2107,8) -> 31 | AF88: =COUNTIFS(Historique!$B$2:$B$2107,2019,Historique!$C$2:$C$2107,8) -> 31 | AH88: =DAY(DATE(2014,9,0)) -> 31 | AI88: =DAY(DATE(2015,9,0)) -> 31 | AJ88: =DAY(DATE(2016,9,0)) -> 31 | AK88: =DAY(DATE(2017,9,0)) -> 31 | AL88: =DAY(DATE(2018,9,0)) -> 31 | AM88: =DAY(DATE(2019,9,0)) -> 31
A89: Septembre | B89: =IF(AA89<AH89,"",IF($B$78="Total vendu",T89,T89/AA89)) -> 1804.594 | C89: =IF(AB89<AI89,"",IF($B$78="Total vendu",U89,U89/AB89)) -> 1679.367 | D89: =IF(AC89<AJ89,"",IF($B$78="Total vendu",V89,V89/AC89)) -> 2049.877 | E89: =IF(AD89<AK89,"",IF($B$78="Total vendu",W89,W89/AD89)) -> 1660.841 | F89: =IF(AE89<AL89,"",IF($B$78="Total vendu",X89,X89/AE89)) -> 1981.374 | G89: =IF(AF89<AM89,"",IF($B$78="Total vendu",Y89,Y89/AF89)) -> 1824.8037 | T89: =SUMIFS(INDEX(Historique!$I$2:$Y$2107,0,Calculs!$C$73),Historique!$B$2:$B$2107,2014,Historique!$C$2:$C$2107,9) -> 1804.594 | U89: =SUMIFS(INDEX(Historique!$I$2:$Y$2107,0,Calculs!$C$73),Historique!$B$2:$B$2107,2015,Historique!$C$2:$C$2107,9) -> 1679.367 | V89: =SUMIFS(INDEX(Historique!$I$2:$Y$2107,0,Calculs!$C$73),Historique!$B$2:$B$2107,2016,Historique!$C$2:$C$2107,9) -> 2049.877 | W89: =SUMIFS(INDEX(Historique!$I$2:$Y$2107,0,Calculs!$C$73),Historique!$B$2:$B$2107,2017,Historique!$C$2:$C$2107,9) -> 1660.841 | X89: =SUMIFS(INDEX(Historique!$I$2:$Y$2107,0,Calculs!$C$73),Historique!$B$2:$B$2107,2018,Historique!$C$2:$C$2107,9) -> 1981.374 | Y89: =SUMIFS(INDEX(Historique!$I$2:$Y$2107,0,Calculs!$C$73),Historique!$B$2:$B$2107,2019,Historique!$C$2:$C$2107,9) -> 1824.8037 | AA89: =COUNTIFS(Historique!$B$2:$B$2107,2014,Historique!$C$2:$C$2107,9) -> 30 | AB89: =COUNTIFS(Historique!$B$2:$B$2107,2015,Historique!$C$2:$C$2107,9) -> 30 | AC89: =COUNTIFS(Historique!$B$2:$B$2107,2016,Historique!$C$2:$C$2107,9) -> 30 | AD89: =COUNTIFS(Historique!$B$2:$B$2107,2017,Historique!$C$2:$C$2107,9) -> 30 | AE89: =COUNTIFS(Historique!$B$2:$B$2107,2018,Historique!$C$2:$C$2107,9) -> 30 | AF89: =COUNTIFS(Historique!$B$2:$B$2107,2019,Historique!$C$2:$C$2107,9) -> 30 | AH89: =DAY(DATE(2014,10,0)) -> 30 | AI89: =DAY(DATE(2015,10,0)) -> 30 | AJ89: =DAY(DATE(2016,10,0)) -> 30 | AK89: =DAY(DATE(2017,10,0)) -> 30 | AL89: =DAY(DATE(2018,10,0)) -> 30 | AM89: =DAY(DATE(2019,10,0)) -> 30
A90: Octobre | B90: =IF(AA90<AH90,"",IF($B$78="Total vendu",T90,T90/AA90)) -> 2049.466 | C90: =IF(AB90<AI90,"",IF($B$78="Total vendu",U90,U90/AB90)) -> 2529.576 | D90: =IF(AC90<AJ90,"",IF($B$78="Total vendu",V90,V90/AC90)) -> 2655.391 | E90: =IF(AD90<AK90,"",IF($B$78="Total vendu",W90,W90/AD90)) -> 2131.123 | F90: =IF(AE90<AL90,"",IF($B$78="Total vendu",X90,X90/AE90)) -> 2195.335 | G90: =IF(AF90<AM90,"",IF($B$78="Total vendu",Y90,Y90/AF90)) | T90: =SUMIFS(INDEX(Historique!$I$2:$Y$2107,0,Calculs!$C$73),Historique!$B$2:$B$2107,2014,Historique!$C$2:$C$2107,10) -> 2049.466 | U90: =SUMIFS(INDEX(Historique!$I$2:$Y$2107,0,Calculs!$C$73),Historique!$B$2:$B$2107,2015,Historique!$C$2:$C$2107,10) -> 2529.576 | V90: =SUMIFS(INDEX(Historique!$I$2:$Y$2107,0,Calculs!$C$73),Historique!$B$2:$B$2107,2016,Historique!$C$2:$C$2107,10) -> 2655.391 | W90: =SUMIFS(INDEX(Historique!$I$2:$Y$2107,0,Calculs!$C$73),Historique!$B$2:$B$2107,2017,Historique!$C$2:$C$2107,10) -> 2131.123 | X90: =SUMIFS(INDEX(Historique!$I$2:$Y$2107,0,Calculs!$C$73),Historique!$B$2:$B$2107,2018,Historique!$C$2:$C$2107,10) -> 2195.335 | Y90: =SUMIFS(INDEX(Historique!$I$2:$Y$2107,0,Calculs!$C$73),Historique!$B$2:$B$2107,2019,Historique!$C$2:$C$2107,10) -> 538.6 | AA90: =COUNTIFS(Historique!$B$2:$B$2107,2014,Historique!$C$2:$C$2107,10) -> 31 | AB90: =COUNTIFS(Historique!$B$2:$B$2107,2015,Historique!$C$2:$C$2107,10) -> 31 | AC90: =COUNTIFS(Historique!$B$2:$B$2107,2016,Historique!$C$2:$C$2107,10) -> 31 | AD90: =COUNTIFS(Historique!$B$2:$B$2107,2017,Historique!$C$2:$C$2107,10) -> 31 | AE90: =COUNTIFS(Historique!$B$2:$B$2107,2018,Historique!$C$2:$C$2107,10) -> 31 | AF90: =COUNTIFS(Historique!$B$2:$B$2107,2019,Historique!$C$2:$C$2107,10) -> 8 | AH90: =DAY(DATE(2014,11,0)) -> 31 | AI90: =DAY(DATE(2015,11,0)) -> 31 | AJ90: =DAY(DATE(2016,11,0)) -> 31 | AK90: =DAY(DATE(2017,11,0)) -> 31 | AL90: =DAY(DATE(2018,11,0)) -> 31 | AM90: =DAY(DATE(2019,11,0)) -> 31
A91: Novembre | B91: =IF(AA91<AH91,"",IF($B$78="Total vendu",T91,T91/AA91)) -> 1770.64 | C91: =IF(AB91<AI91,"",IF($B$78="Total vendu",U91,U91/AB91)) -> 2106.888 | D91: =IF(AC91<AJ91,"",IF($B$78="Total vendu",V91,V91/AC91)) -> 1942.5993 | E91: =IF(AD91<AK91,"",IF($B$78="Total vendu",W91,W91/AD91)) -> 1705.579 | F91: =IF(AE91<AL91,"",IF($B$78="Total vendu",X91,X91/AE91)) -> 2008.677 | G91: =IF(AF91<AM91,"",IF($B$78="Total vendu",Y91,Y91/AF91)) | T91: =SUMIFS(INDEX(Historique!$I$2:$Y$2107,0,Calculs!$C$73),Historique!$B$2:$B$2107,2014,Historique!$C$2:$C$2107,11) -> 1770.64 | U91: =SUMIFS(INDEX(Historique!$I$2:$Y$2107,0,Calculs!$C$73),Historique!$B$2:$B$2107,2015,Historique!$C$2:$C$2107,11) -> 2106.888 | V91: =SUMIFS(INDEX(Historique!$I$2:$Y$2107,0,Calculs!$C$73),Historique!$B$2:$B$2107,2016,Historique!$C$2:$C$2107,11) -> 1942.5993 | W91: =SUMIFS(INDEX(Historique!$I$2:$Y$2107,0,Calculs!$C$73),Historique!$B$2:$B$2107,2017,Historique!$C$2:$C$2107,11) -> 1705.579 | X91: =SUMIFS(INDEX(Historique!$I$2:$Y$2107,0,Calculs!$C$73),Historique!$B$2:$B$2107,2018,Historique!$C$2:$C$2107,11) -> 2008.677 | Y91: =SUMIFS(INDEX(Historique!$I$2:$Y$2107,0,Calculs!$C$73),Historique!$B$2:$B$2107,2019,Historique!$C$2:$C$2107,11) -> 0 | AA91: =COUNTIFS(Historique!$B$2:$B$2107,2014,Historique!$C$2:$C$2107,11) -> 30 | AB91: =COUNTIFS(Historique!$B$2:$B$2107,2015,Historique!$C$2:$C$2107,11) -> 30 | AC91: =COUNTIFS(Historique!$B$2:$B$2107,2016,Historique!$C$2:$C$2107,11) -> 30 | AD91: =COUNTIFS(Historique!$B$2:$B$2107,2017,Historique!$C$2:$C$2107,11) -> 30 | AE91: =COUNTIFS(Historique!$B$2:$B$2107,2018,Historique!$C$2:$C$2107,11) -> 30 | AF91: =COUNTIFS(Historique!$B$2:$B$2107,2019,Historique!$C$2:$C$2107,11) -> 0 | AH91: =DAY(DATE(2014,12,0)) -> 30 | AI91: =DAY(DATE(2015,12,0)) -> 30 | AJ91: =DAY(DATE(2016,12,0)) -> 30 | AK91: =DAY(DATE(2017,12,0)) -> 30 | AL91: =DAY(DATE(2018,12,0)) -> 30 | AM91: =DAY(DATE(2019,12,0)) -> 30
A92: Décembre | B92: =IF(AA92<AH92,"",IF($B$78="Total vendu",T92,T92/AA92)) -> 2173.086 | C92: =IF(AB92<AI92,"",IF($B$78="Total vendu",U92,U92/AB92)) -> 2340.76 | D92: =IF(AC92<AJ92,"",IF($B$78="Total vendu",V92,V92/AC92)) -> 2681.985 | E92: =IF(AD92<AK92,"",IF($B$78="Total vendu",W92,W92/AD92)) -> 1966.602 | F92: =IF(AE92<AL92,"",IF($B$78="Total vendu",X92,X92/AE92)) -> 2507.947 | G92: =IF(AF92<AM92,"",IF($B$78="Total vendu",Y92,Y92/AF92)) | T92: =SUMIFS(INDEX(Historique!$I$2:$Y$2107,0,Calculs!$C$73),Historique!$B$2:$B$2107,2014,Historique!$C$2:$C$2107,12) -> 2173.086 | U92: =SUMIFS(INDEX(Historique!$I$2:$Y$2107,0,Calculs!$C$73),Historique!$B$2:$B$2107,2015,Historique!$C$2:$C$2107,12) -> 2340.76 | V92: =SUMIFS(INDEX(Historique!$I$2:$Y$2107,0,Calculs!$C$73),Historique!$B$2:$B$2107,2016,Historique!$C$2:$C$2107,12) -> 2681.985 | W92: =SUMIFS(INDEX(Historique!$I$2:$Y$2107,0,Calculs!$C$73),Historique!$B$2:$B$2107,2017,Historique!$C$2:$C$2107,12) -> 1966.602 | X92: =SUMIFS(INDEX(Historique!$I$2:$Y$2107,0,Calculs!$C$73),Historique!$B$2:$B$2107,2018,Historique!$C$2:$C$2107,12) -> 2507.947 | Y92: =SUMIFS(INDEX(Historique!$I$2:$Y$2107,0,Calculs!$C$73),Historique!$B$2:$B$2107,2019,Historique!$C$2:$C$2107,12) -> 0 | AA92: =COUNTIFS(Historique!$B$2:$B$2107,2014,Historique!$C$2:$C$2107,12) -> 31 | AB92: =COUNTIFS(Historique!$B$2:$B$2107,2015,Historique!$C$2:$C$2107,12) -> 31 | AC92: =COUNTIFS(Historique!$B$2:$B$2107,2016,Historique!$C$2:$C$2107,12) -> 31 | AD92: =COUNTIFS(Historique!$B$2:$B$2107,2017,Historique!$C$2:$C$2107,12) -> 31 | AE92: =COUNTIFS(Historique!$B$2:$B$2107,2018,Historique!$C$2:$C$2107,12) -> 31 | AF92: =COUNTIFS(Historique!$B$2:$B$2107,2019,Historique!$C$2:$C$2107,12) -> 0 | AH92: =DAY(DATE(2014,13,0)) -> 31 | AI92: =DAY(DATE(2015,13,0)) -> 31 | AJ92: =DAY(DATE(2016,13,0)) -> 31 | AK92: =DAY(DATE(2017,13,0)) -> 31 | AL92: =DAY(DATE(2018,13,0)) -> 31 | AM92: =DAY(DATE(2019,13,0)) -> 31
A93: =IF($B$78="Total vendu","Total","Moyenne") -> Total | B93: =IF(SUMPRODUCT((AA81:AA92=AH81:AH92)*AA81:AA92)=0,"",IF($B$78="Total vendu",SUMPRODUCT((AA81:AA92=AH81:AH92)*T81:T92),SUMPRODUCT((AA81:AA92=AH81:AH92)*T81:T92)/SUMPRODUCT((AA81:AA92=AH81:AH92)*AA81:AA92))) -> 18556.309 | C93: =IF(SUMPRODUCT((AB81:AB92=AI81:AI92)*AB81:AB92)=0,"",IF($B$78="Total vendu",SUMPRODUCT((AB81:AB92=AI81:AI92)*U81:U92),SUMPRODUCT((AB81:AB92=AI81:AI92)*U81:U92)/SUMPRODUCT((AB81:AB92=AI81:AI92)*AB81:AB92))) -> 23057.574 | D93: =IF(SUMPRODUCT((AC81:AC92=AJ81:AJ92)*AC81:AC92)=0,"",IF($B$78="Total vendu",SUMPRODUCT((AC81:AC92=AJ81:AJ92)*V81:V92),SUMPRODUCT((AC81:AC92=AJ81:AJ92)*V81:V92)/SUMPRODUCT((AC81:AC92=AJ81:AJ92)*AC81:AC92))) -> 25559.626 | E93: =IF(SUMPRODUCT((AD81:AD92=AK81:AK92)*AD81:AD92)=0,"",IF($B$78="Total vendu",SUMPRODUCT((AD81:AD92=AK81:AK92)*W81:W92),SUMPRODUCT((AD81:AD92=AK81:AK92)*W81:W92)/SUMPRODUCT((AD81:AD92=AK81:AK92)*AD81:AD92))) -> 19362.431 | F93: =IF(SUMPRODUCT((AE81:AE92=AL81:AL92)*AE81:AE92)=0,"",IF($B$78="Total vendu",SUMPRODUCT((AE81:AE92=AL81:AL92)*X81:X92),SUMPRODUCT((AE81:AE92=AL81:AL92)*X81:X92)/SUMPRODUCT((AE81:AE92=AL81:AL92)*AE81:AE92))) -> 23354.228 | G93: =IF(SUMPRODUCT((AF81:AF92=AM81:AM92)*AF81:AF92)=0,"",IF($B$78="Total vendu",SUMPRODUCT((AF81:AF92=AM81:AM92)*Y81:Y92),SUMPRODUCT((AF81:AF92=AM81:AM92)*Y81:Y92)/SUMPRODUCT((AF81:AF92=AM81:AM92)*AF81:AF92))) -> 16880.288
A95: Suit le filtre Médicament. Plus la case est foncée, plus le mois a vendu. Seuls les mois complets sont affichés et comptés dans le total de l'année.

Sheet Environnement
A1: Environnement | J1: =HYPERLINK("#Accueil!A1","← Accueil") -> ← Accueil | K1: =HYPERLINK("#Activite!A1","Activité") -> Activité | U1: =IF($U$2,"Une année moyenne : ventes, semaine par semaine","Une année moyenne : "&INDEX({"épidémie de grippe","gastro-entérite","varicelle","température","pollens"},$U$3)&" et ventes, semaine par semaine") -> Une année moyenne : ventes, semaine par semaine
A2: Ventes hebdomadaires de la pharmacie comparées à une donnée publique externe. | U2: =$B$3="Tous" -> TRUE
A3: Facteur | B3: Tous | U3: =IFERROR(MATCH($B$3,{"Grippe","Gastro-entérite","Varicelle","Température","Pollens"},0),1) -> 1
A4: Source | B4: =IF($U$2,"Réseau Sentinelles (grippe, gastro-entérite, varicelle) ; Météo-France (température) ; RNSA (pollens)",INDEX({"Réseau Sentinelles — Inserm, Sorbonne Université (sentiweb.fr)","Réseau Sentinelles — Inserm, Sorbonne Université (sentiweb.fr)","Réseau Sentinelles — Inserm, Sorbonne Université (sentiweb.fr)","Météo-France (meteo.data.gouv.fr)","RNSA — Réseau national de surveillance aérobiologique (pollens.fr)"},$U$3)) -> Réseau Sentinelles (grippe, gastro-entérite, varicelle) ; Météo-France (température) ; RNSA (pollens)
A5: Indicateur | B5: =IF($U$2,"Incidences hebdomadaires France entière pour 100 000 habitants ; température moyenne près de Montpellier (°C) ; pollens de graminées à Montpellier (grains / m³)",INDEX({"Incidence hebdomadaire des syndromes grippaux, pour 100 000 habitants","Incidence hebdomadaire des diarrhées aiguës, France entière, pour 100 000 habitants","Incidence hebdomadaire de la varicelle, France entière, pour 100 000 habitants","Température moyenne quotidienne (TNTXM) des stations à moins de 25 km de Montpellier, moyenne de la semaine, en °C","Pollens de graminées, capteur de Montpellier, moyenne de la semaine, en grains par m³ et par jour"},$U$3)) -> Incidences hebdomadaires France entière pour 100 000 habitants ; température moyenne près de Montpellier (°C) ; pollens de graminées à Montpellier (grains / m³)
A6: Accès | B6: =IF($U$2,"API publique du Réseau Sentinelles ; data.gouv.fr (Météo-France, RNSA), extraction du 12/10/2026",INDEX({"API publique : www.sentiweb.fr/api/v1/datasets/rest/incidence (indicator=3, geo=PAY), extraction du 09/10/2026","API publique : www.sentiweb.fr/api/v1/datasets/rest/incidence (indicator=6, geo=PAY), extraction du 12/10/2026","API publique : www.sentiweb.fr/api/v1/datasets/rest/incidence (indicator=7, geo=PAY), extraction du 12/10/2026","data.gouv.fr : Données climatologiques de base - quotidiennes (Météo-France), extraction du 12/10/2026","data.gouv.fr : Données historiques de surveillance des pollens et des moisissures (RNSA), extraction du 12/10/2026"},$U$3)) -> API publique du Réseau Sentinelles ; data.gouv.fr (Météo-France, RNSA), extraction du 12/10/2026
A7: Fichier | B7: =IF($U$2,"dashboard/externe/epidemies_france_hebdo.csv, meteo_hebdo.csv, pollens_hebdo.csv",INDEX({"data/externe/sentinelles_syndromes_grippaux_france_2014_2019.csv","dashboard/externe/epidemies_france_hebdo.csv","dashboard/externe/epidemies_france_hebdo.csv","dashboard/externe/meteo_hebdo.csv","dashboard/externe/pollens_hebdo.csv"},$U$3)) -> dashboard/externe/epidemies_france_hebdo.csv, meteo_hebdo.csv, pollens_hebdo.csv
A9: Résultat
A10: Code ATC | B10: =IF($U$2,"Grippe","Les ventes et "&INDEX({"la grippe","la gastro-entérite","la varicelle","la température","les pollens"},$U$3)) -> Grippe | C10: =IF($U$2,"Gastro-entérite","Part des hausses et baisses de ventes liée à "&INDEX({"la grippe","la gastro-entérite","la varicelle","la température","les pollens"},$U$3)) -> Gastro-entérite | D10: =IF($U$2,"Varicelle","") -> Varicelle | E10: =IF($U$2,"Température","") -> Température | F10: =IF($U$2,"Pollens","") -> Pollens
A11: M01AB | B11: =IF($U$2,IF(COUNT($U$61:$U$360)<10,"",IF(ABS(CORREL($U$61:$U$360,$D$61:$D$360))<0.2,"",IF(CORREL($U$61:$U$360,$D$61:$D$360)>0,"Hausse","Baisse")&" ("&ROUND(RSQ($D$61:$D$360,$U$61:$U$360)*100,0)&" %)")),IF(ABS(CORREL($C$61:$C$360,$D$61:$D$360))<0.2,"",IF(CORREL($C$61:$C$360,$D$61:$D$360)>0,INDEX({"Hausse","Hausse","Hausse","Hausse au chaud","Hausse"},$U$3),INDEX({"Baisse","Baisse","Baisse","Hausse au froid","Baisse"},$U$3)))) | C11: =IF($U$2,IF(COUNT($V$61:$V$360)<10,"",IF(ABS(CORREL($V$61:$V$360,$D$61:$D$360))<0.2,"",IF(CORREL($V$61:$V$360,$D$61:$D$360)>0,"Hausse","Baisse")&" ("&ROUND(RSQ($D$61:$D$360,$V$61:$V$360)*100,0)&" %)")),IF(B11="","",RSQ($D$61:$D$360,$C$61:$C$360))) | D11: =IF($U$2,IF(COUNT($W$61:$W$360)<10,"",IF(ABS(CORREL($W$61:$W$360,$D$61:$D$360))<0.2,"",IF(CORREL($W$61:$W$360,$D$61:$D$360)>0,"Hausse","Baisse")&" ("&ROUND(RSQ($D$61:$D$360,$W$61:$W$360)*100,0)&" %)")),"") | E11: =IF($U$2,IF(COUNT($X$61:$X$360)<10,"",IF(ABS(CORREL($X$61:$X$360,$D$61:$D$360))<0.2,"",IF(CORREL($X$61:$X$360,$D$61:$D$360)>0,"Hausse au chaud","Hausse au froid")&" ("&ROUND(RSQ($D$61:$D$360,$X$61:$X$360)*100,0)&" %)")),"") | F11: =IF($U$2,IF(COUNT($Y$61:$Y$360)<10,"",IF(ABS(CORREL($Y$61:$Y$360,$D$61:$D$360))<0.2,"",IF(CORREL($Y$61:$Y$360,$D$61:$D$360)>0,"Hausse","Baisse")&" ("&ROUND(RSQ($D$61:$D$360,$Y$61:$Y$360)*100,0)&" %)")),"")
A12: M01AE | B12: =IF($U$2,IF(COUNT($U$61:$U$360)<10,"",IF(ABS(CORREL($U$61:$U$360,$E$61:$E$360))<0.2,"",IF(CORREL($U$61:$U$360,$E$61:$E$360)>0,"Hausse","Baisse")&" ("&ROUND(RSQ($E$61:$E$360,$U$61:$U$360)*100,0)&" %)")),IF(ABS(CORREL($C$61:$C$360,$E$61:$E$360))<0.2,"",IF(CORREL($C$61:$C$360,$E$61:$E$360)>0,INDEX({"Hausse","Hausse","Hausse","Hausse au chaud","Hausse"},$U$3),INDEX({"Baisse","Baisse","Baisse","Hausse au froid","Baisse"},$U$3)))) -> Hausse (15 %) | C12: =IF($U$2,IF(COUNT($V$61:$V$360)<10,"",IF(ABS(CORREL($V$61:$V$360,$E$61:$E$360))<0.2,"",IF(CORREL($V$61:$V$360,$E$61:$E$360)>0,"Hausse","Baisse")&" ("&ROUND(RSQ($E$61:$E$360,$V$61:$V$360)*100,0)&" %)")),IF(B12="","",RSQ($E$61:$E$360,$C$61:$C$360))) -> Hausse (7 %) | D12: =IF($U$2,IF(COUNT($W$61:$W$360)<10,"",IF(ABS(CORREL($W$61:$W$360,$E$61:$E$360))<0.2,"",IF(CORREL($W$61:$W$360,$E$61:$E$360)>0,"Hausse","Baisse")&" ("&ROUND(RSQ($E$61:$E$360,$W$61:$W$360)*100,0)&" %)")),"") | E12: =IF($U$2,IF(COUNT($X$61:$X$360)<10,"",IF(ABS(CORREL($X$61:$X$360,$E$61:$E$360))<0.2,"",IF(CORREL($X$61:$X$360,$E$61:$E$360)>0,"Hausse au chaud","Hausse au froid")&" ("&ROUND(RSQ($E$61:$E$360,$X$61:$X$360)*100,0)&" %)")),"") -> Hausse au froid (9 %) | F12: =IF($U$2,IF(COUNT($Y$61:$Y$360)<10,"",IF(ABS(CORREL($Y$61:$Y$360,$E$61:$E$360))<0.2,"",IF(CORREL($Y$61:$Y$360,$E$61:$E$360)>0,"Hausse","Baisse")&" ("&ROUND(RSQ($E$61:$E$360,$Y$61:$Y$360)*100,0)&" %)")),"")
A13: N02BA | B13: =IF($U$2,IF(COUNT($U$61:$U$360)<10,"",IF(ABS(CORREL($U$61:$U$360,$F$61:$F$360))<0.2,"",IF(CORREL($U$61:$U$360,$F$61:$F$360)>0,"Hausse","Baisse")&" ("&ROUND(RSQ($F$61:$F$360,$U$61:$U$360)*100,0)&" %)")),IF(ABS(CORREL($C$61:$C$360,$F$61:$F$360))<0.2,"",IF(CORREL($C$61:$C$360,$F$61:$F$360)>0,INDEX({"Hausse","Hausse","Hausse","Hausse au chaud","Hausse"},$U$3),INDEX({"Baisse","Baisse","Baisse","Hausse au froid","Baisse"},$U$3)))) -> Hausse (6 %) | C13: =IF($U$2,IF(COUNT($V$61:$V$360)<10,"",IF(ABS(CORREL($V$61:$V$360,$F$61:$F$360))<0.2,"",IF(CORREL($V$61:$V$360,$F$61:$F$360)>0,"Hausse","Baisse")&" ("&ROUND(RSQ($F$61:$F$360,$V$61:$V$360)*100,0)&" %)")),IF(B13="","",RSQ($F$61:$F$360,$C$61:$C$360))) -> Hausse (15 %) | D13: =IF($U$2,IF(COUNT($W$61:$W$360)<10,"",IF(ABS(CORREL($W$61:$W$360,$F$61:$F$360))<0.2,"",IF(CORREL($W$61:$W$360,$F$61:$F$360)>0,"Hausse","Baisse")&" ("&ROUND(RSQ($F$61:$F$360,$W$61:$W$360)*100,0)&" %)")),"") | E13: =IF($U$2,IF(COUNT($X$61:$X$360)<10,"",IF(ABS(CORREL($X$61:$X$360,$F$61:$F$360))<0.2,"",IF(CORREL($X$61:$X$360,$F$61:$F$360)>0,"Hausse au chaud","Hausse au froid")&" ("&ROUND(RSQ($F$61:$F$360,$X$61:$X$360)*100,0)&" %)")),"") -> Hausse au froid (8 %) | F13: =IF($U$2,IF(COUNT($Y$61:$Y$360)<10,"",IF(ABS(CORREL($Y$61:$Y$360,$F$61:$F$360))<0.2,"",IF(CORREL($Y$61:$Y$360,$F$61:$F$360)>0,"Hausse","Baisse")&" ("&ROUND(RSQ($F$61:$F$360,$Y$61:$Y$360)*100,0)&" %)")),"")
A14: N02BE | B14: =IF($U$2,IF(COUNT($U$61:$U$360)<10,"",IF(ABS(CORREL($U$61:$U$360,$G$61:$G$360))<0.2,"",IF(CORREL($U$61:$U$360,$G$61:$G$360)>0,"Hausse","Baisse")&" ("&ROUND(RSQ($G$61:$G$360,$U$61:$U$360)*100,0)&" %)")),IF(ABS(CORREL($C$61:$C$360,$G$61:$G$360))<0.2,"",IF(CORREL($C$61:$C$360,$G$61:$G$360)>0,INDEX({"Hausse","Hausse","Hausse","Hausse au chaud","Hausse"},$U$3),INDEX({"Baisse","Baisse","Baisse","Hausse au froid","Baisse"},$U$3)))) -> Hausse (17 %) | C14: =IF($U$2,IF(COUNT($V$61:$V$360)<10,"",IF(ABS(CORREL($V$61:$V$360,$G$61:$G$360))<0.2,"",IF(CORREL($V$61:$V$360,$G$61:$G$360)>0,"Hausse","Baisse")&" ("&ROUND(RSQ($G$61:$G$360,$V$61:$V$360)*100,0)&" %)")),IF(B14="","",RSQ($G$61:$G$360,$C$61:$C$360))) -> Hausse (34 %) | D14: =IF($U$2,IF(COUNT($W$61:$W$360)<10,"",IF(ABS(CORREL($W$61:$W$360,$G$61:$G$360))<0.2,"",IF(CORREL($W$61:$W$360,$G$61:$G$360)>0,"Hausse","Baisse")&" ("&ROUND(RSQ($G$61:$G$360,$W$61:$W$360)*100,0)&" %)")),"") | E14: =IF($U$2,IF(COUNT($X$61:$X$360)<10,"",IF(ABS(CORREL($X$61:$X$360,$G$61:$G$360))<0.2,"",IF(CORREL($X$61:$X$360,$G$61:$G$360)>0,"Hausse au chaud","Hausse au froid")&" ("&ROUND(RSQ($G$61:$G$360,$X$61:$X$360)*100,0)&" %)")),"") -> Hausse au froid (33 %) | F14: =IF($U$2,IF(COUNT($Y$61:$Y$360)<10,"",IF(ABS(CORREL($Y$61:$Y$360,$G$61:$G$360))<0.2,"",IF(CORREL($Y$61:$Y$360,$G$61:$G$360)>0,"Hausse","Baisse")&" ("&ROUND(RSQ($G$61:$G$360,$Y$61:$Y$360)*100,0)&" %)")),"") -> Baisse (7 %)
A15: N05B | B15: =IF($U$2,IF(COUNT($U$61:$U$360)<10,"",IF(ABS(CORREL($U$61:$U$360,$H$61:$H$360))<0.2,"",IF(CORREL($U$61:$U$360,$H$61:$H$360)>0,"Hausse","Baisse")&" ("&ROUND(RSQ($H$61:$H$360,$U$61:$U$360)*100,0)&" %)")),IF(ABS(CORREL($C$61:$C$360,$H$61:$H$360))<0.2,"",IF(CORREL($C$61:$C$360,$H$61:$H$360)>0,INDEX({"Hausse","Hausse","Hausse","Hausse au chaud","Hausse"},$U$3),INDEX({"Baisse","Baisse","Baisse","Hausse au froid","Baisse"},$U$3)))) | C15: =IF($U$2,IF(COUNT($V$61:$V$360)<10,"",IF(ABS(CORREL($V$61:$V$360,$H$61:$H$360))<0.2,"",IF(CORREL($V$61:$V$360,$H$61:$H$360)>0,"Hausse","Baisse")&" ("&ROUND(RSQ($H$61:$H$360,$V$61:$V$360)*100,0)&" %)")),IF(B15="","",RSQ($H$61:$H$360,$C$61:$C$360))) -> Hausse (7 %) | D15: =IF($U$2,IF(COUNT($W$61:$W$360)<10,"",IF(ABS(CORREL($W$61:$W$360,$H$61:$H$360))<0.2,"",IF(CORREL($W$61:$W$360,$H$61:$H$360)>0,"Hausse","Baisse")&" ("&ROUND(RSQ($H$61:$H$360,$W$61:$W$360)*100,0)&" %)")),"") | E15: =IF($U$2,IF(COUNT($X$61:$X$360)<10,"",IF(ABS(CORREL($X$61:$X$360,$H$61:$H$360))<0.2,"",IF(CORREL($X$61:$X$360,$H$61:$H$360)>0,"Hausse au chaud","Hausse au froid")&" ("&ROUND(RSQ($H$61:$H$360,$X$61:$X$360)*100,0)&" %)")),"") | F15: =IF($U$2,IF(COUNT($Y$61:$Y$360)<10,"",IF(ABS(CORREL($Y$61:$Y$360,$H$61:$H$360))<0.2,"",IF(CORREL($Y$61:$Y$360,$H$61:$H$360)>0,"Hausse","Baisse")&" ("&ROUND(RSQ($H$61:$H$360,$Y$61:$Y$360)*100,0)&" %)")),"")
A16: N05C | B16: =IF($U$2,IF(COUNT($U$61:$U$360)<10,"",IF(ABS(CORREL($U$61:$U$360,$I$61:$I$360))<0.2,"",IF(CORREL($U$61:$U$360,$I$61:$I$360)>0,"Hausse","Baisse")&" ("&ROUND(RSQ($I$61:$I$360,$U$61:$U$360)*100,0)&" %)")),IF(ABS(CORREL($C$61:$C$360,$I$61:$I$360))<0.2,"",IF(CORREL($C$61:$C$360,$I$61:$I$360)>0,INDEX({"Hausse","Hausse","Hausse","Hausse au chaud","Hausse"},$U$3),INDEX({"Baisse","Baisse","Baisse","Hausse au froid","Baisse"},$U$3)))) | C16: =IF($U$2,IF(COUNT($V$61:$V$360)<10,"",IF(ABS(CORREL($V$61:$V$360,$I$61:$I$360))<0.2,"",IF(CORREL($V$61:$V$360,$I$61:$I$360)>0,"Hausse","Baisse")&" ("&ROUND(RSQ($I$61:$I$360,$V$61:$V$360)*100,0)&" %)")),IF(B16="","",RSQ($I$61:$I$360,$C$61:$C$360))) | D16: =IF($U$2,IF(COUNT($W$61:$W$360)<10,"",IF(ABS(CORREL($W$61:$W$360,$I$61:$I$360))<0.2,"",IF(CORREL($W$61:$W$360,$I$61:$I$360)>0,"Hausse","Baisse")&" ("&ROUND(RSQ($I$61:$I$360,$W$61:$W$360)*100,0)&" %)")),"") | E16: =IF($U$2,IF(COUNT($X$61:$X$360)<10,"",IF(ABS(CORREL($X$61:$X$360,$I$61:$I$360))<0.2,"",IF(CORREL($X$61:$X$360,$I$61:$I$360)>0,"Hausse au chaud","Hausse au froid")&" ("&ROUND(RSQ($I$61:$I$360,$X$61:$X$360)*100,0)&" %)")),"") | F16: =IF($U$2,IF(COUNT($Y$61:$Y$360)<10,"",IF(ABS(CORREL($Y$61:$Y$360,$I$61:$I$360))<0.2,"",IF(CORREL($Y$61:$Y$360,$I$61:$I$360)>0,"Hausse","Baisse")&" ("&ROUND(RSQ($I$61:$I$360,$Y$61:$Y$360)*100,0)&" %)")),"")
A17: R03 | B17: =IF($U$2,IF(COUNT($U$61:$U$360)<10,"",IF(ABS(CORREL($U$61:$U$360,$J$61:$J$360))<0.2,"",IF(CORREL($U$61:$U$360,$J$61:$J$360)>0,"Hausse","Baisse")&" ("&ROUND(RSQ($J$61:$J$360,$U$61:$U$360)*100,0)&" %)")),IF(ABS(CORREL($C$61:$C$360,$J$61:$J$360))<0.2,"",IF(CORREL($C$61:$C$360,$J$61:$J$360)>0,INDEX({"Hausse","Hausse","Hausse","Hausse au chaud","Hausse"},$U$3),INDEX({"Baisse","Baisse","Baisse","Hausse au froid","Baisse"},$U$3)))) -> Hausse (8 %) | C17: =IF($U$2,IF(COUNT($V$61:$V$360)<10,"",IF(ABS(CORREL($V$61:$V$360,$J$61:$J$360))<0.2,"",IF(CORREL($V$61:$V$360,$J$61:$J$360)>0,"Hausse","Baisse")&" ("&ROUND(RSQ($J$61:$J$360,$V$61:$V$360)*100,0)&" %)")),IF(B17="","",RSQ($J$61:$J$360,$C$61:$C$360))) -> Hausse (8 %) | D17: =IF($U$2,IF(COUNT($W$61:$W$360)<10,"",IF(ABS(CORREL($W$61:$W$360,$J$61:$J$360))<0.2,"",IF(CORREL($W$61:$W$360,$J$61:$J$360)>0,"Hausse","Baisse")&" ("&ROUND(RSQ($J$61:$J$360,$W$61:$W$360)*100,0)&" %)")),"") | E17: =IF($U$2,IF(COUNT($X$61:$X$360)<10,"",IF(ABS(CORREL($X$61:$X$360,$J$61:$J$360))<0.2,"",IF(CORREL($X$61:$X$360,$J$61:$J$360)>0,"Hausse au chaud","Hausse au froid")&" ("&ROUND(RSQ($J$61:$J$360,$X$61:$X$360)*100,0)&" %)")),"") -> Hausse au froid (21 %) | F17: =IF($U$2,IF(COUNT($Y$61:$Y$360)<10,"",IF(ABS(CORREL($Y$61:$Y$360,$J$61:$J$360))<0.2,"",IF(CORREL($Y$61:$Y$360,$J$61:$J$360)>0,"Hausse","Baisse")&" ("&ROUND(RSQ($J$61:$J$360,$Y$61:$Y$360)*100,0)&" %)")),"")
A18: R06 | B18: =IF($U$2,IF(COUNT($U$61:$U$360)<10,"",IF(ABS(CORREL($U$61:$U$360,$K$61:$K$360))<0.2,"",IF(CORREL($U$61:$U$360,$K$61:$K$360)>0,"Hausse","Baisse")&" ("&ROUND(RSQ($K$61:$K$360,$U$61:$U$360)*100,0)&" %)")),IF(ABS(CORREL($C$61:$C$360,$K$61:$K$360))<0.2,"",IF(CORREL($C$61:$C$360,$K$61:$K$360)>0,INDEX({"Hausse","Hausse","Hausse","Hausse au chaud","Hausse"},$U$3),INDEX({"Baisse","Baisse","Baisse","Hausse au froid","Baisse"},$U$3)))) -> Baisse (10 %) | C18: =IF($U$2,IF(COUNT($V$61:$V$360)<10,"",IF(ABS(CORREL($V$61:$V$360,$K$61:$K$360))<0.2,"",IF(CORREL($V$61:$V$360,$K$61:$K$360)>0,"Hausse","Baisse")&" ("&ROUND(RSQ($K$61:$K$360,$V$61:$V$360)*100,0)&" %)")),IF(B18="","",RSQ($K$61:$K$360,$C$61:$C$360))) -> Baisse (28 %) | D18: =IF($U$2,IF(COUNT($W$61:$W$360)<10,"",IF(ABS(CORREL($W$61:$W$360,$K$61:$K$360))<0.2,"",IF(CORREL($W$61:$W$360,$K$61:$K$360)>0,"Hausse","Baisse")&" ("&ROUND(RSQ($K$61:$K$360,$W$61:$W$360)*100,0)&" %)")),"") -> Hausse (19 %) | E18: =IF($U$2,IF(COUNT($X$61:$X$360)<10,"",IF(ABS(CORREL($X$61:$X$360,$K$61:$K$360))<0.2,"",IF(CORREL($X$61:$X$360,$K$61:$K$360)>0,"Hausse au chaud","Hausse au froid")&" ("&ROUND(RSQ($K$61:$K$360,$X$61:$X$360)*100,0)&" %)")),"") -> Hausse au chaud (12 %) | F18: =IF($U$2,IF(COUNT($Y$61:$Y$360)<10,"",IF(ABS(CORREL($Y$61:$Y$360,$K$61:$K$360))<0.2,"",IF(CORREL($Y$61:$Y$360,$K$61:$K$360)>0,"Hausse","Baisse")&" ("&ROUND(RSQ($K$61:$K$360,$Y$61:$Y$360)*100,0)&" %)")),"") -> Hausse (11 %)
A19: Toutes ventes | B19: =IF($U$2,IF(COUNT($U$61:$U$360)<10,"",IF(ABS(CORREL($U$61:$U$360,$L$61:$L$360))<0.2,"",IF(CORREL($U$61:$U$360,$L$61:$L$360)>0,"Hausse","Baisse")&" ("&ROUND(RSQ($L$61:$L$360,$U$61:$U$360)*100,0)&" %)")),IF(ABS(CORREL($C$61:$C$360,$L$61:$L$360))<0.2,"",IF(CORREL($C$61:$C$360,$L$61:$L$360)>0,INDEX({"Hausse","Hausse","Hausse","Hausse au chaud","Hausse"},$U$3),INDEX({"Baisse","Baisse","Baisse","Hausse au froid","Baisse"},$U$3)))) -> Hausse (18 %) | C19: =IF($U$2,IF(COUNT($V$61:$V$360)<10,"",IF(ABS(CORREL($V$61:$V$360,$L$61:$L$360))<0.2,"",IF(CORREL($V$61:$V$360,$L$61:$L$360)>0,"Hausse","Baisse")&" ("&ROUND(RSQ($L$61:$L$360,$V$61:$V$360)*100,0)&" %)")),IF(B19="","",RSQ($L$61:$L$360,$C$61:$C$360))) -> Hausse (34 %) | D19: =IF($U$2,IF(COUNT($W$61:$W$360)<10,"",IF(ABS(CORREL($W$61:$W$360,$L$61:$L$360))<0.2,"",IF(CORREL($W$61:$W$360,$L$61:$L$360)>0,"Hausse","Baisse")&" ("&ROUND(RSQ($L$61:$L$360,$W$61:$W$360)*100,0)&" %)")),"") | E19: =IF($U$2,IF(COUNT($X$61:$X$360)<10,"",IF(ABS(CORREL($X$61:$X$360,$L$61:$L$360))<0.2,"",IF(CORREL($X$61:$X$360,$L$61:$L$360)>0,"Hausse au chaud","Hausse au froid")&" ("&ROUND(RSQ($L$61:$L$360,$X$61:$X$360)*100,0)&" %)")),"") -> Hausse au froid (36 %) | F19: =IF($U$2,IF(COUNT($Y$61:$Y$360)<10,"",IF(ABS(CORREL($Y$61:$Y$360,$L$61:$L$360))<0.2,"",IF(CORREL($Y$61:$Y$360,$L$61:$L$360)>0,"Hausse","Baisse")&" ("&ROUND(RSQ($L$61:$L$360,$Y$61:$Y$360)*100,0)&" %)")),"") -> Baisse (5 %)
A21: =IF($U$2,"Hausse ou baisse : sens dans lequel les ventes évoluent avec le facteur ; entre parenthèses, part des hausses et baisses des ventes qui vont de pair avec lui. Case vide : pas de lien.",IF(C19="","","Exemple : "&ROUND(C19*100,0)&" % pour toutes les ventes signifie que, d'une semaine à l'autre, "&ROUND(C19*100,0)&" % des hausses et des baisses des ventes vont de pair avec "&INDEX({"l'épidémie de grippe en France","la gastro-entérite en France","la varicelle en France","la température à Montpellier","les pollens de graminées à Montpellier"},$U$3)&" ; les "&(100-ROUND(C19*100,0))&" % restants dépendent d'autres facteurs.")) -> Hausse ou baisse : sens dans lequel les ventes évoluent avec le facteur ; entre parenthèses, part des hausses et baisses des ventes qui vont de pair avec lui. Case vide : pas de lien.
A22: Population, médecins, revenus, accès et concurrence se mesurent par commune (INSEE, Annuaire santé) : l'adresse de la pharmacie ne figure pas dans l'export.
A24: =IF($U$2,"Pic moyen de chaque facteur","Pic "&INDEX({"de l'épidémie","de l'épidémie","de l'épidémie","de température","des pollens"},$U$3)&", hiver par hiver") -> Pic moyen de chaque facteur
A25: =IF($U$2,"Facteur","Hiver") -> Facteur | B25: =IF($U$2,"Pic moyen","Semaine du pic") -> Pic moyen | C25: =IF($U$2,"","Lundi") | D25: =IF($U$2,"",INDEX({"Cas / 100 000 hab.","Cas / 100 000 hab.","Cas / 100 000 hab.","Température (°C)","Graminées (grains / m³)"},$U$3)) | E25: =IF($U$2,"","Ventes de la semaine") | F25: =IF($U$2,"","Vs semaine moyenne")
A26: =IF($U$2,"Grippe","2013-2014") -> Grippe | B26: =IF($U$2,IF(DAY(DATE(2019,1,3)+7*(INDEX($P$61:$P$112,MATCH(MAX($Z$61:$Z$112),$Z$61:$Z$112,0))-1))<=10,"Début ",IF(DAY(DATE(2019,1,3)+7*(INDEX($P$61:$P$112,MATCH(MAX($Z$61:$Z$112),$Z$61:$Z$112,0))-1))<=20,"Mi-","Fin "))&LOWER(INDEX(Calculs!$A$6:$A$17,MONTH(DATE(2019,1,3)+7*(INDEX($P$61:$P$112,MATCH(MAX($Z$61:$Z$112),$Z$61:$Z$112,0))-1)))),INDEX($A$61:$A$88,MATCH(MAX($C$61:$C$88),$C$61:$C$88,0))) -> Début février | C26: =IF($U$2,"",INDEX($B$61:$B$88,MATCH(MAX($C$61:$C$88),$C$61:$C$88,0))) | D26: =IF($U$2,"",MAX($C$61:$C$88)) | E26: =IF($U$2,"",INDEX($L$61:$L$88,MATCH(MAX($C$61:$C$88),$C$61:$C$88,0))) | F26: =IF($U$2,"",E26/AVERAGE($L$61:$L$360)-1)
A27: =IF($U$2,"Gastro-entérite","2014-2015") -> Gastro-entérite | B27: =IF($U$2,IF(DAY(DATE(2019,1,3)+7*(INDEX($P$61:$P$112,MATCH(MAX($AA$61:$AA$112),$AA$61:$AA$112,0))-1))<=10,"Début ",IF(DAY(DATE(2019,1,3)+7*(INDEX($P$61:$P$112,MATCH(MAX($AA$61:$AA$112),$AA$61:$AA$112,0))-1))<=20,"Mi-","Fin "))&LOWER(INDEX(Calculs!$A$6:$A$17,MONTH(DATE(2019,1,3)+7*(INDEX($P$61:$P$112,MATCH(MAX($AA$61:$AA$112),$AA$61:$AA$112,0))-1)))),INDEX($A$89:$A$140,MATCH(MAX($C$89:$C$140),$C$89:$C$140,0))) -> Début janvier | C27: =IF($U$2,"",INDEX($B$89:$B$140,MATCH(MAX($C$89:$C$140),$C$89:$C$140,0))) | D27: =IF($U$2,"",MAX($C$89:$C$140)) | E27: =IF($U$2,"",INDEX($L$89:$L$140,MATCH(MAX($C$89:$C$140),$C$89:$C$140,0))) | F27: =IF($U$2,"",E27/AVERAGE($L$61:$L$360)-1)
A28: =IF($U$2,"Varicelle","2015-2016") -> Varicelle | B28: =IF($U$2,IF(DAY(DATE(2019,1,3)+7*(INDEX($P$61:$P$112,MATCH(MAX($AB$61:$AB$112),$AB$61:$AB$112,0))-1))<=10,"Début ",IF(DAY(DATE(2019,1,3)+7*(INDEX($P$61:$P$112,MATCH(MAX($AB$61:$AB$112),$AB$61:$AB$112,0))-1))<=20,"Mi-","Fin "))&LOWER(INDEX(Calculs!$A$6:$A$17,MONTH(DATE(2019,1,3)+7*(INDEX($P$61:$P$112,MATCH(MAX($AB$61:$AB$112),$AB$61:$AB$112,0))-1)))),INDEX($A$141:$A$193,MATCH(MAX($C$141:$C$193),$C$141:$C$193,0))) -> Mi-avril | C28: =IF($U$2,"",INDEX($B$141:$B$193,MATCH(MAX($C$141:$C$193),$C$141:$C$193,0))) | D28: =IF($U$2,"",MAX($C$141:$C$193)) | E28: =IF($U$2,"",INDEX($L$141:$L$193,MATCH(MAX($C$141:$C$193),$C$141:$C$193,0))) | F28: =IF($U$2,"",E28/AVERAGE($L$61:$L$360)-1)
A29: =IF($U$2,"Chaleur","2016-2017") -> Chaleur | B29: =IF($U$2,IF(DAY(DATE(2019,1,3)+7*(INDEX($P$61:$P$112,MATCH(MAX($AC$61:$AC$112),$AC$61:$AC$112,0))-1))<=10,"Début ",IF(DAY(DATE(2019,1,3)+7*(INDEX($P$61:$P$112,MATCH(MAX($AC$61:$AC$112),$AC$61:$AC$112,0))-1))<=20,"Mi-","Fin "))&LOWER(INDEX(Calculs!$A$6:$A$17,MONTH(DATE(2019,1,3)+7*(INDEX($P$61:$P$112,MATCH(MAX($AC$61:$AC$112),$AC$61:$AC$112,0))-1)))),INDEX($A$194:$A$245,MATCH(MAX($C$194:$C$245),$C$194:$C$245,0))) -> Fin juillet | C29: =IF($U$2,"",INDEX($B$194:$B$245,MATCH(MAX($C$194:$C$245),$C$194:$C$245,0))) | D29: =IF($U$2,"",MAX($C$194:$C$245)) | E29: =IF($U$2,"",INDEX($L$194:$L$245,MATCH(MAX($C$194:$C$245),$C$194:$C$245,0))) | F29: =IF($U$2,"",E29/AVERAGE($L$61:$L$360)-1)
A30: =IF($U$2,"Pollens","2017-2018") -> Pollens | B30: =IF($U$2,IF(DAY(DATE(2019,1,3)+7*(INDEX($P$61:$P$112,MATCH(MAX($AD$61:$AD$112),$AD$61:$AD$112,0))-1))<=10,"Début ",IF(DAY(DATE(2019,1,3)+7*(INDEX($P$61:$P$112,MATCH(MAX($AD$61:$AD$112),$AD$61:$AD$112,0))-1))<=20,"Mi-","Fin "))&LOWER(INDEX(Calculs!$A$6:$A$17,MONTH(DATE(2019,1,3)+7*(INDEX($P$61:$P$112,MATCH(MAX($AD$61:$AD$112),$AD$61:$AD$112,0))-1)))),INDEX($A$246:$A$297,MATCH(MAX($C$246:$C$297),$C$246:$C$297,0))) -> Mi-juin | C30: =IF($U$2,"",INDEX($B$246:$B$297,MATCH(MAX($C$246:$C$297),$C$246:$C$297,0))) | D30: =IF($U$2,"",MAX($C$246:$C$297)) | E30: =IF($U$2,"",INDEX($L$246:$L$297,MATCH(MAX($C$246:$C$297),$C$246:$C$297,0))) | F30: =IF($U$2,"",E30/AVERAGE($L$61:$L$360)-1)
A31: =IF($U$2,"Ventes (tous médicaments)","2018-2019") -> Ventes (tous médicaments) | B31: =IF($U$2,IF(DAY(DATE(2019,1,3)+7*(INDEX($P$61:$P$112,MATCH(MAX($S$61:$S$112),$S$61:$S$112,0))-1))<=10,"Début ",IF(DAY(DATE(2019,1,3)+7*(INDEX($P$61:$P$112,MATCH(MAX($S$61:$S$112),$S$61:$S$112,0))-1))<=20,"Mi-","Fin "))&LOWER(INDEX(Calculs!$A$6:$A$17,MONTH(DATE(2019,1,3)+7*(INDEX($P$61:$P$112,MATCH(MAX($S$61:$S$112),$S$61:$S$112,0))-1)))),INDEX($A$298:$A$349,MATCH(MAX($C$298:$C$349),$C$298:$C$349,0))) -> Fin décembre | C31: =IF($U$2,"",INDEX($B$298:$B$349,MATCH(MAX($C$298:$C$349),$C$298:$C$349,0))) | D31: =IF($U$2,"",MAX($C$298:$C$349)) | E31: =IF($U$2,"",INDEX($L$298:$L$349,MATCH(MAX($C$298:$C$349),$C$298:$C$349,0))) | F31: =IF($U$2,"",E31/AVERAGE($L$61:$L$360)-1)
A32: =IF($U$2,"Pic moyen : moment de l'année où la moyenne 2014-2019 est la plus haute.","Hiver = semaine 30 d'une année à semaine 29 de la suivante. Vs semaine moyenne : ventes totales comparées à la moyenne des 300 semaines.") -> Pic moyen : moment de l'année où la moyenne 2014-2019 est la plus haute.
A34: =IF($U$2,"","Pic moyen "&INDEX({"de l'épidémie","de l'épidémie","de l'épidémie","de température","des pollens"},$U$3)) | B34: =IF($U$2,"","Semaine "&INDEX($P$61:$P$112,MATCH(MAX($R$61:$R$112),$R$61:$R$112,0)))
A35: =IF($U$2,"","Pic moyen des ventes") | B35: =IF($U$2,"","Semaine "&INDEX($P$61:$P$112,MATCH(MAX($S$61:$S$112),$S$61:$S$112,0)))
A59: Données hebdomadaires comparées
A60: Semaine | B60: Lundi | C60: =IF($U$2,"",INDEX({"Grippe (cas / 100 000 hab.)","Gastro-entérite (cas / 100 000 hab.)","Varicelle (cas / 100 000 hab.)","Température à Montpellier (°C)","Graminées à Montpellier (grains / m³)"},$U$3)) | D60: M01AB | E60: M01AE | F60: N02BA | G60: N02BE | H60: N05B | I60: N05C | J60: R03 | K60: R06 | L60: Total | N60: N° semaine | P60: N° semaine | Q60: Repère | R60: =IF($U$2,"",INDEX({"Grippe moyenne","Gastro moyenne","Varicelle moyenne","Température moyenne","Pollens moyens"},$U$3)) | S60: Ventes moyennes | U60: Grippe | V60: Gastro-entérite | W60: Varicelle | X60: Température | Y60: Pollens | Z60: Grippe | AA60: Gastro-entérite | AB60: Varicelle | AC60: Température | AD60: Pollens
A61: 2014-S02 | B61: 41645 | C61: =IF(OR($U$2,INDEX($U61:$Y61,$U$3)=""),"",INDEX($U61:$Y61,$U$3)) | D61: =SUMIFS(Historique!I$2:I$2107,Historique!$A$2:$A$2107,">="&$B61,Historique!$A$2:$A$2107,"<="&($B61+6),Historique!$H$2:$H$2107,"Oui") -> 33.66 | E61: =SUMIFS(Historique!J$2:J$2107,Historique!$A$2:$A$2107,">="&$B61,Historique!$A$2:$A$2107,"<="&($B61+6),Historique!$H$2:$H$2107,"Oui") -> 13.34 | F61: =SUMIFS(Historique!K$2:K$2107,Historique!$A$2:$A$2107,">="&$B61,Historique!$A$2:$A$2107,"<="&($B61+6),Historique!$H$2:$H$2107,"Oui") -> 40.4 | G61: =SUMIFS(Historique!L$2:L$2107,Historique!$A$2:$A$2107,">="&$B61,Historique!$A$2:$A$2107,"<="&($B61+6),Historique!$H$2:$H$2107,"Oui") -> 227.7 | H61: =SUMIFS(Historique!M$2:M$2107,Historique!$A$2:$A$2107,">="&$B61,Historique!$A$2:$A$2107,"<="&($B61+6),Historique!$H$2:$H$2107,"Oui") -> 94 | I61: =SUMIFS(Historique!N$2:N$2107,Historique!$A$2:$A$2107,">="&$B61,Historique!$A$2:$A$2107,"<="&($B61+6),Historique!$H$2:$H$2107,"Oui") -> 5 | J61: =SUMIFS(Historique!O$2:O$2107,Historique!$A$2:$A$2107,">="&$B61,Historique!$A$2:$A$2107,"<="&($B61+6),Historique!$H$2:$H$2107,"Oui") -> 24 | K61: =SUMIFS(Historique!P$2:P$2107,Historique!$A$2:$A$2107,">="&$B61,Historique!$A$2:$A$2107,"<="&($B61+6),Historique!$H$2:$H$2107,"Oui") -> 11.2 | L61: =SUM(D61:K61) -> 449.3 | N61: 2 | P61: 1 | Q61: Janv. | R61: =IF($U$2,NA(),AVERAGEIF($N$61:$N$360,P61,$C$61:$C$360)) -> #N/A | S61: =AVERAGEIF($N$61:$N$360,P61,$L$61:$L$360) -> 591.2616 | U61: 73 | V61: 245 | W61: 19 | X61: 10.531429 | Z61: =IFERROR(AVERAGEIF($N$61:$N$360,$P61,$U$61:$U$360),"") -> 200.2 | AA61: =IFERROR(AVERAGEIF($N$61:$N$360,$P61,$V$61:$V$360),"") -> 201.4 | AB61: =IFERROR(AVERAGEIF($N$61:$N$360,$P61,$W$61:$W$360),"") -> 20.4 | AC61: =IFERROR(AVERAGEIF($N$61:$N$360,$P61,$X$61:$X$360),"") -> 7.9012245 | AD61: =IFERROR(AVERAGEIF($N$61:$N$360,$P61,$Y$61:$Y$360),"") -> 0.325
A62: 2014-S03 | B62: 41652 | C62: =IF(OR($U$2,INDEX($U62:$Y62,$U$3)=""),"",INDEX($U62:$Y62,$U$3)) | D62: =SUMIFS(Historique!I$2:I$2107,Historique!$A$2:$A$2107,">="&$B62,Historique!$A$2:$A$2107,"<="&($B62+6),Historique!$H$2:$H$2107,"Oui") -> 30.67 | E62: =SUMIFS(Historique!J$2:J$2107,Historique!$A$2:$A$2107,">="&$B62,Historique!$A$2:$A$2107,"<="&($B62+6),Historique!$H$2:$H$2107,"Oui") -> 26.34 | F62: =SUMIFS(Historique!K$2:K$2107,Historique!$A$2:$A$2107,">="&$B62,Historique!$A$2:$A$2107,"<="&($B62+6),Historique!$H$2:$H$2107,"Oui") -> 45.9 | G62: =SUMIFS(Historique!L$2:L$2107,Historique!$A$2:$A$2107,">="&$B62,Historique!$A$2:$A$2107,"<="&($B62+6),Historique!$H$2:$H$2107,"Oui") -> 218.4 | H62: =SUMIFS(Historique!M$2:M$2107,Historique!$A$2:$A$2107,">="&$B62,Historique!$A$2:$A$2107,"<="&($B62+6),Historique!$H$2:$H$2107,"Oui") -> 80 | I62: =SUMIFS(Historique!N$2:N$2107,Historique!$A$2:$A$2107,">="&$B62,Historique!$A$2:$A$2107,"<="&($B62+6),Historique!$H$2:$H$2107,"Oui") -> 8 | J62: =SUMIFS(Historique!O$2:O$2107,Historique!$A$2:$A$2107,">="&$B62,Historique!$A$2:$A$2107,"<="&($B62+6),Historique!$H$2:$H$2107,"Oui") -> 29 | K62: =SUMIFS(Historique!P$2:P$2107,Historique!$A$2:$A$2107,">="&$B62,Historique!$A$2:$A$2107,"<="&($B62+6),Historique!$H$2:$H$2107,"Oui") -> 12 | L62: =SUM(D62:K62) -> 450.31 | N62: 3 | P62: 2 | R62: =IF($U$2,NA(),AVERAGEIF($N$61:$N$360,P62,$C$61:$C$360)) -> #N/A | S62: =AVERAGEIF($N$61:$N$360,P62,$L$61:$L$360) -> 575.02 | U62: 100 | V62: 243 | W62: 20 | X62: 8.6 | Z62: =IFERROR(AVERAGEIF($N$61:$N$360,$P62,$U$61:$U$360),"") -> 186.5 | AA62: =IFERROR(AVERAGEIF($N$61:$N$360,$P62,$V$61:$V$360),"") -> 213.5 | AB62: =IFERROR(AVERAGEIF($N$61:$N$360,$P62,$W$61:$W$360),"") -> 16.333333 | AC62: =IFERROR(AVERAGEIF($N$61:$N$360,$P62,$X$61:$X$360),"") -> 7.697415 | AD62: =IFERROR(AVERAGEIF($N$61:$N$360,$P62,$Y$61:$Y$360),"") -> 0
A63: 2014-S04 | B63: 41659 | C63: =IF(OR($U$2,INDEX($U63:$Y63,$U$3)=""),"",INDEX($U63:$Y63,$U$3)) | D63: =SUMIFS(Historique!I$2:I$2107,Historique!$A$2:$A$2107,">="&$B63,Historique!$A$2:$A$2107,"<="&($B63+6),Historique!$H$2:$H$2107,"Oui") -> 34 | E63: =SUMIFS(Historique!J$2:J$2107,Historique!$A$2:$A$2107,">="&$B63,Historique!$A$2:$A$2107,"<="&($B63+6),Historique!$H$2:$H$2107,"Oui") -> 32.37 | F63: =SUMIFS(Historique!K$2:K$2107,Historique!$A$2:$A$2107,">="&$B63,Historique!$A$2:$A$2107,"<="&($B63+6),Historique!$H$2:$H$2107,"Oui") -> 31.5 | G63: =SUMIFS(Historique!L$2:L$2107,Historique!$A$2:$A$2107,">="&$B63,Historique!$A$2:$A$2107,"<="&($B63+6),Historique!$H$2:$H$2107,"Oui") -> 179.6 | H63: =SUMIFS(Historique!M$2:M$2107,Historique!$A$2:$A$2107,">="&$B63,Historique!$A$2:$A$2107,"<="&($B63+6),Historique!$H$2:$H$2107,"Oui") -> 80 | I63: =SUMIFS(Historique!N$2:N$2107,Historique!$A$2:$A$2107,">="&$B63,Historique!$A$2:$A$2107,"<="&($B63+6),Historique!$H$2:$H$2107,"Oui") -> 8 | J63: =SUMIFS(Historique!O$2:O$2107,Historique!$A$2:$A$2107,">="&$B63,Historique!$A$2:$A$2107,"<="&($B63+6),Historique!$H$2:$H$2107,"Oui") -> 23 | K63: =SUMIFS(Historique!P$2:P$2107,Historique!$A$2:$A$2107,">="&$B63,Historique!$A$2:$A$2107,"<="&($B63+6),Historique!$H$2:$H$2107,"Oui") -> 10 | L63: =SUM(D63:K63) -> 398.47 | N63: 4 | P63: 3 | R63: =IF($U$2,NA(),AVERAGEIF($N$61:$N$360,P63,$C$61:$C$360)) -> #N/A | S63: =AVERAGEIF($N$61:$N$360,P63,$L$61:$L$360) -> 532.54433 | U63: 133 | V63: 236 | W63: 25 | X63: 8.1085714 | Y63: 0.68 | Z63: =IFERROR(AVERAGEIF($N$61:$N$360,$P63,$U$61:$U$360),"") -> 226.5 | AA63: =IFERROR(AVERAGEIF($N$61:$N$360,$P63,$V$61:$V$360),"") -> 207.16667 | AB63: =IFERROR(AVERAGEIF($N$61:$N$360,$P63,$W$61:$W$360),"") -> 16.166667 | AC63: =IFERROR(AVERAGEIF($N$61:$N$360,$P63,$X$61:$X$360),"") -> 7.2234694 | AD63: =IFERROR(AVERAGEIF($N$61:$N$360,$P63,$Y$61:$Y$360),"") -> 0.485
A64: 2014-S05 | B64: 41666 | C64: =IF(OR($U$2,INDEX($U64:$Y64,$U$3)=""),"",INDEX($U64:$Y64,$U$3)) | D64: =SUMIFS(Historique!I$2:I$2107,Historique!$A$2:$A$2107,">="&$B64,Historique!$A$2:$A$2107,"<="&($B64+6),Historique!$H$2:$H$2107,"Oui") -> 31.02 | E64: =SUMIFS(Historique!J$2:J$2107,Historique!$A$2:$A$2107,">="&$B64,Historique!$A$2:$A$2107,"<="&($B64+6),Historique!$H$2:$H$2107,"Oui") -> 23.35 | F64: =SUMIFS(Historique!K$2:K$2107,Historique!$A$2:$A$2107,">="&$B64,Historique!$A$2:$A$2107,"<="&($B64+6),Historique!$H$2:$H$2107,"Oui") -> 20.7 | G64: =SUMIFS(Historique!L$2:L$2107,Historique!$A$2:$A$2107,">="&$B64,Historique!$A$2:$A$2107,"<="&($B64+6),Historique!$H$2:$H$2107,"Oui") -> 159.88 | H64: =SUMIFS(Historique!M$2:M$2107,Historique!$A$2:$A$2107,">="&$B64,Historique!$A$2:$A$2107,"<="&($B64+6),Historique!$H$2:$H$2107,"Oui") -> 84 | I64: =SUMIFS(Historique!N$2:N$2107,Historique!$A$2:$A$2107,">="&$B64,Historique!$A$2:$A$2107,"<="&($B64+6),Historique!$H$2:$H$2107,"Oui") -> 12 | J64: =SUMIFS(Historique!O$2:O$2107,Historique!$A$2:$A$2107,">="&$B64,Historique!$A$2:$A$2107,"<="&($B64+6),Historique!$H$2:$H$2107,"Oui") -> 29 | K64: =SUMIFS(Historique!P$2:P$2107,Historique!$A$2:$A$2107,">="&$B64,Historique!$A$2:$A$2107,"<="&($B64+6),Historique!$H$2:$H$2107,"Oui") -> 12 | L64: =SUM(D64:K64) -> 371.95 | N64: 5 | P64: 4 | R64: =IF($U$2,NA(),AVERAGEIF($N$61:$N$360,P64,$C$61:$C$360)) -> #N/A | S64: =AVERAGEIF($N$61:$N$360,P64,$L$61:$L$360) -> 539.06617 | U64: 187 | V64: 226 | W64: 19 | X64: 6.76 | Y64: 0.68 | Z64: =IFERROR(AVERAGEIF($N$61:$N$360,$P64,$U$61:$U$360),"") -> 306.83333 | AA64: =IFERROR(AVERAGEIF($N$61:$N$360,$P64,$V$61:$V$360),"") -> 197.16667 | AB64: =IFERROR(AVERAGEIF($N$61:$N$360,$P64,$W$61:$W$360),"") -> 20.833333 | AC64: =IFERROR(AVERAGEIF($N$61:$N$360,$P64,$X$61:$X$360),"") -> 7.7740136 | AD64: =IFERROR(AVERAGEIF($N$61:$N$360,$P64,$Y$61:$Y$360),"") -> 0.39392857
